<robot name="brutus" version="1.0">
  <!--Generated by RobotCAD, a ROS Workbench for FreeCAD (https://github.com/drfenixion/freecad.robotcad)-->
  <joint name="chasis_to_cover" type="fixed">
    <parent link="base_link"/>
    <child link="chasis_cover_link"/>
    <origin rpy="0 0 0" xyz="0.0 0.0 0.0208"/>
  </joint>
  <joint name="cover_to_fr_spacer" type="fixed">
    <parent link="chasis_cover_link"/>
    <child link="spacer_fr"/>
    <origin rpy="0 0 0" xyz="0.023 0.023 0.0015"/>
  </joint>
  <joint name="cover_to_fl_spacer" type="fixed">
    <parent link="chasis_cover_link"/>
    <child link="spacer_fl"/>
    <origin rpy="0 0 0" xyz="-0.023 0.023 0.0015"/>
  </joint>
  <joint name="cover_to_br_spacer" type="fixed">
    <parent link="chasis_cover_link"/>
    <child link="spacer_br"/>
    <origin rpy="0 0 0" xyz="0.023 -0.023 0.0015"/>
  </joint>
  <joint name="cover_to_bl_spacer" type="fixed">
    <parent link="chasis_cover_link"/>
    <child link="spacer_bl"/>
    <origin rpy="0 0 0" xyz="-0.023 -0.023 0.0015"/>
  </joint>
  <joint name="00_spacer_to_leg_elbow_br" type="revolute">
    <parent link="spacer_br"/>
    <child link="leg_elbow_br"/>
    <origin rpy="0 0 0" xyz="0.0 0.0 -0.0175"/>
    <axis xyz="0 0 1"/>
    <limit effort="0.17" lower="-1.0471975511965976" upper="1.0471975511965976" velocity="10.471975511965978"/>
  </joint>
  <joint name="10_spacer_to_leg_elbow_bl" type="revolute">
    <parent link="spacer_bl"/>
    <child link="leg_elbow_bl"/>
    <origin rpy="0 0 0" xyz="0.0 0.0 -0.0175"/>
    <axis xyz="0 0 1"/>
    <limit effort="0.17" lower="-1.0471975511965976" upper="1.0471975511965976" velocity="10.471975511965978"/>
  </joint>
  <joint name="20_spacer_to_leg_elbow_fl" type="revolute">
    <parent link="spacer_fl"/>
    <child link="leg_elbow_fl"/>
    <origin rpy="0 0 0" xyz="0.0 0.0 -0.0175"/>
    <axis xyz="0 0 1"/>
    <limit effort="0.17" lower="-1.0471975511965976" upper="1.0471975511965976" velocity="10.471975511965978"/>
  </joint>
  <joint name="30_spacer_to_leg_elbow_fr" type="revolute">
    <parent link="spacer_fr"/>
    <child link="leg_elbow_fr"/>
    <origin rpy="0 0 0" xyz="0.0 0.0 -0.0175"/>
    <axis xyz="0 0 1"/>
    <limit effort="0.17" lower="-1.0471975511965976" upper="1.0471975511965976" velocity="10.471975511965978"/>
  </joint>
  <joint name="leg_elbow_to_leg_upper_axis_br" type="fixed">
    <parent link="leg_elbow_br"/>
    <child link="leg_upper_axis_br"/>
    <origin rpy="-1.5707963267948968 0 3.141592653589793" xyz="0.036 0.009 0.017"/>
  </joint>
  <joint name="leg_upper_axis_to_upper_link_br" type="fixed">
    <parent link="leg_upper_axis_br"/>
    <child link="upper_link_br"/>
    <origin rpy="0 0 0" xyz="0.0 0.0 0.01197"/>
  </joint>
  <joint name="leg_elbow_to_leg_upper_axis_bl" type="fixed">
    <parent link="leg_elbow_bl"/>
    <child link="leg_upper_axis_bl"/>
    <origin rpy="-1.5707963267948968 0 0" xyz="-0.036 -0.015 0.017"/>
  </joint>
  <joint name="leg_upper_axis_to_upper_link_bl" type="fixed">
    <parent link="leg_upper_axis_bl"/>
    <child link="upper_link_bl"/>
    <origin rpy="0 0 0" xyz="0.0 0.0 0.01197"/>
  </joint>
  <joint name="leg_upper_axis_to_upper_link_fl" type="fixed">
    <parent link="leg_upper_axis_fl"/>
    <child link="upper_link_fl"/>
    <origin rpy="0 0 0" xyz="0.0 0.0 0.01197"/>
  </joint>
  <joint name="leg_elbow_to_leg_upper_axis_fl" type="fixed">
    <parent link="leg_elbow_fl"/>
    <child link="leg_upper_axis_fl"/>
    <origin rpy="-1.5707963267948963 0 0" xyz="-0.036 -0.009 0.017"/>
  </joint>
  <joint name="leg_elbow_to_leg_upper_axis_fr" type="fixed">
    <parent link="leg_elbow_fr"/>
    <child link="leg_upper_axis_fr"/>
    <origin rpy="-1.5707963267948968 0 3.141592653589793" xyz="0.036 0.015 0.017"/>
  </joint>
  <joint name="leg_upper_axis_to_upper_link_fr" type="fixed">
    <parent link="leg_upper_axis_fr"/>
    <child link="upper_link_fr"/>
    <origin rpy="0 0 0" xyz="0.0 0.0 0.01197"/>
  </joint>
  <joint name="leg_elbow_to_leg_bottom_axis_br" type="fixed">
    <parent link="leg_elbow_br"/>
    <child link="leg_bottom_axis_br"/>
    <origin rpy="1.5707963267948963 0 0" xyz="0.02425 0.0 -0.0049"/>
  </joint>
  <joint name="leg_elbow_to_leg_bottom_axis_fl" type="fixed">
    <parent link="leg_elbow_fl"/>
    <child link="leg_bottom_axis_fl"/>
    <origin rpy="1.5707963267948968 0 3.141592653589793" xyz="-0.024 0.0 -0.0049"/>
  </joint>
  <joint name="01_leg_bottom_axis_to_leg_bottom_link_br" type="revolute">
    <parent link="leg_bottom_axis_br"/>
    <child link="leg_bottom_link_br"/>
    <origin rpy="0 0 0" xyz="0.0 0.0 0.0261"/>
    <axis xyz="0 0 1"/>
    <limit effort="0.17" lower="-1.0471975511965976" upper="1.0471975511965976" velocity="10.471975511965978"/>
  </joint>
  <joint name="21_leg_bottom_axis_to_leg_bottom_link_fl" type="revolute">
    <parent link="leg_bottom_axis_fl"/>
    <child link="leg_bottom_link_fl"/>
    <origin rpy="0 0 0" xyz="0.0 0.0 0.0261"/>
    <axis xyz="0 0 1"/>
    <limit effort="0.17" lower="-1.0471975511965976" upper="1.0471975511965976" velocity="10.471975511965978"/>
  </joint>
  <joint name="11_leg_bottom_axis_to_leg_bottom_link_bl" type="revolute">
    <parent link="leg_bottom_axis_bl"/>
    <child link="leg_bottom_link_bl"/>
    <origin rpy="0 0 0" xyz="0.0 0.0 0.0261"/>
    <axis xyz="0 0 1"/>
    <limit effort="0.17" lower="-1.0471975511965976" upper="1.0471975511965976" velocity="10.471975511965978"/>
  </joint>
  <joint name="leg_elbow_to_leg_bottom_axis_bl" type="fixed">
    <parent link="leg_elbow_bl"/>
    <child link="leg_bottom_axis_bl"/>
    <origin rpy="1.5707963267948963 0 0" xyz="-0.024 0.0 -0.0049"/>
  </joint>
  <joint name="leg_elbow_to_leg_bottom_axis_fr" type="fixed">
    <parent link="leg_elbow_fr"/>
    <child link="leg_bottom_axis_fr"/>
    <origin rpy="1.5707963267948968 0 -3.141592653589793" xyz="0.024 0.0 -0.0049"/>
  </joint>
  <joint name="31_leg_bottom_axis_to_leg_bottom_link_fr" type="revolute">
    <parent link="leg_bottom_axis_fr"/>
    <child link="leg_bottom_link_fr"/>
    <origin rpy="0 0 0" xyz="0.0 0.0 0.0261"/>
    <axis xyz="0 0 1"/>
    <limit effort="0.17" lower="-1.0471975511965976" upper="1.0471975511965976" velocity="10.471975511965978"/>
  </joint>
  <joint name="leg_bottom_link_to_foot_axis_fr" type="fixed">
    <parent link="leg_bottom_link_fr"/>
    <child link="foot_axis_fr"/>
    <origin rpy="0 0 0" xyz="-0.042 -0.01 -0.02935"/>
  </joint>
  <joint name="32_foot_axis_to_foot_link_fr" type="revolute">
    <parent link="foot_axis_fr"/>
    <child link="foot_link_fr"/>
    <origin rpy="0 0 0" xyz="0.0 0.0 0.0065"/>
    <axis xyz="0 0 1"/>
    <limit effort="-0.17" lower="-1.0471975511965976" upper="1.0471975511965976" velocity="10.471975511965978"/>
  </joint>
  <joint name="leg_bottom_link_to_foot_axis_br" type="fixed">
    <parent link="leg_bottom_link_br"/>
    <child link="foot_axis_br"/>
    <origin rpy="3.141592653589793 0 3.141592653589793" xyz="0.042 -0.01 -0.02935"/>
  </joint>
  <joint name="02_foot_axis_to_foot_link_br" type="revolute">
    <parent link="foot_axis_br"/>
    <child link="foot_link_br"/>
    <origin rpy="0 0 0" xyz="0.0 0.0 -0.0065"/>
    <axis xyz="0 0 1"/>
    <limit effort="0.17" lower="-1.0471975511965976" upper="1.0471975511965976" velocity="10.471975511965978"/>
  </joint>
  <joint name="leg_bottom_link_to_foot_axis_fl" type="fixed">
    <parent link="leg_bottom_link_fl"/>
    <child link="foot_axis_fl"/>
    <origin rpy="3.141592653589793 0 3.141592653589793" xyz="0.042 -0.01 -0.01635"/>
  </joint>
  <joint name="22_foot_axis_to_foot_link_fl" type="revolute">
    <parent link="foot_axis_fl"/>
    <child link="foot_link_fl"/>
    <origin rpy="0 0 0" xyz="0.0 0.0 0.0065"/>
    <axis xyz="0 0 1"/>
    <limit effort="0.17" lower="-1.0471975511965976" upper="1.0471975511965976" velocity="10.471975511965978"/>
  </joint>
  <joint name="leg_bottom_link_to_foot_axis_bl" type="fixed">
    <parent link="leg_bottom_link_bl"/>
    <child link="foot_axis_bl"/>
    <origin rpy="0 0 0" xyz="-0.042 -0.01 -0.02935"/>
  </joint>
  <joint name="12_foot_axis_to_foot_link_bl" type="revolute">
    <parent link="foot_axis_bl"/>
    <child link="foot_link_bl"/>
    <origin rpy="0 0 0" xyz="0.0 0.0 0.0065"/>
    <axis xyz="0 0 1"/>
    <limit effort="0.17" lower="-1.0471975511965976" upper="1.0471975511965976" velocity="10.471975511965978"/>
  </joint>
  <joint name="chasis_to_servo_br" type="fixed">
    <parent link="base_link"/>
    <child link="servo_br_chasis"/>
    <origin rpy="3.141592653589793 0 -1.5707963267948968" xyz="-0.023 -0.0168 0.00035"/>
  </joint>
  <joint name="chasis_to_servo_fr" type="fixed">
    <parent link="base_link"/>
    <child link="servo_fr_chasis"/>
    <origin rpy="3.141592653589793 0 1.5707963267948968" xyz="-0.023 0.0168 0.00035"/>
  </joint>
  <joint name="chasis_to_servo_bl" type="fixed">
    <parent link="base_link"/>
    <child link="servo_bl_chasis"/>
    <origin rpy="3.141592653589793 0 1.5707963267948968" xyz="0.023 0.0168 0.00035"/>
  </joint>
  <joint name="chasis_to_servo_fl" type="fixed">
    <parent link="base_link"/>
    <child link="servo_fl_chasis"/>
    <origin rpy="3.141592653589793 0 -1.5707963267948968" xyz="0.023 -0.0168 0.00035"/>
  </joint>
  <joint name="elbow_to_servo_br" type="fixed">
    <parent link="leg_elbow_br"/>
    <child link="servo_br_leg"/>
    <origin rpy="1.5707963267948966 1.5707963267948963 0" xyz="0.02425 -0.0117 0.00125"/>
  </joint>
  <joint name="elbow_to_servo_fr" type="fixed">
    <parent link="leg_elbow_fr"/>
    <child link="servo_fr_leg"/>
    <origin rpy="-1.5707963267948966 1.5707963267948963 0" xyz="0.02425 0.0117 0.00125"/>
  </joint>
  <joint name="elbow_to_servo_bl" type="fixed">
    <parent link="leg_elbow_bl"/>
    <child link="servo_bl_leg"/>
    <origin rpy="1.5707963267948966 1.5707963267948963 0" xyz="-0.02425 -0.0117 0.00125"/>
  </joint>
  <joint name="elbow_to_servo_fl" type="fixed">
    <parent link="leg_elbow_fl"/>
    <child link="servo_fl_leg"/>
    <origin rpy="-1.5707963267948966 1.5707963267948963 0" xyz="-0.02425 0.0117 0.00125"/>
  </joint>
  <joint name="cover_to_box" type="fixed">
    <parent link="chasis_cover_link"/>
    <child link="up_box_link"/>
    <origin rpy="0 0 0" xyz="0.0 0.0 0.008"/>
  </joint>
  <joint name="box_to_battery" type="fixed">
    <parent link="up_box_link"/>
    <child link="battery"/>
    <origin rpy="0 0 0" xyz="-0.028 -0.035 0.005"/>
  </joint>






  <link name="base_link">
    <visual>
      <!--chasis_solid001/chasis_solid001.-->
      <origin rpy="0 0 0" xyz="0.0 0.0 0.0"/>
      <geometry>
        <mesh filename="../meshes/robot_chasis_solid_gh7xs0.dae"/>
      </geometry>
    </visual>
    <collision>
      <!--chasis_solid-->
      <origin rpy="0 0 0" xyz="0.0 0.0 0.0"/>
      <geometry>
        <mesh filename="../meshes/robot_chasis_solid_wpln47.dae"/>
      </geometry>
    </collision>
    <inertial>
        <mass value="0.00485"/>
        <origin xyz="0 0 0" rpy="0 0 0"/>
        <inertia ixx="0.00485" ixy="0" ixz="0" iyy="0.00485" iyz="0" izz="0.00485"/>
    </inertial>
  </link>
  <link name="chasis_cover_link">
    <visual>
      <!--chasis_top001/chasis_top001.-->
      <origin rpy="0 0 3.141592653589793" xyz="0.0 0.0 0.0"/>
      <geometry>
        <mesh filename="../meshes/robot_chasis_top_rj7fnb.dae"/>
      </geometry>
    </visual>
    <collision>
      <!--chasis_top-->
      <origin rpy="0 0 0" xyz="0.0 0.0 0.0"/>
      <geometry>
        <mesh filename="../meshes/robot_chasis_top_9hl3hy.dae"/>
      </geometry>
    </collision>
    <inertial>
        <mass value="0.00335"/>
        <origin xyz="0 0 0" rpy="0 0 0"/>
        <inertia ixx="0.00335" ixy="0" ixz="0" iyy="0.00335" iyz="0" izz="0.00335"/>
    </inertial>
  </link>

  <link name="spacer_fr">
    <visual>
      <!--spacer_body001/spacer_body002.-->
      <origin rpy="0 0 0" xyz="0.0 0.0 0.0"/>
      <geometry>
        <mesh filename="../meshes/robot_spacer_body_pfkzkm.dae"/>
      </geometry>
    </visual>
    <collision>
      <!--spacer_body001/spacer_body002.-->
      <origin rpy="0 0 0" xyz="0.0 0.0 0.0"/>
      <geometry>
        <mesh filename="../meshes/robot_spacer_body_ykg5ow.dae"/>
      </geometry>
    </collision>
    <inertial>
        <mass value="0.00004"/>
        <origin xyz="0 0 0" rpy="0 0 0"/>
        <inertia ixx="0.00004" ixy="0" ixz="0" iyy="0.00004" iyz="0" izz="0.00004"/>
    </inertial>
  </link>
  <link name="spacer_fl">
    <visual>
      <!--spacer_body003/spacer_body004.-->
      <origin rpy="0 0 0" xyz="0.0 0.0 0.0"/>
      <geometry>
        <mesh filename="../meshes/robot_spacer_body_qm9ood.dae"/>
      </geometry>
    </visual>
    <collision>
      <!--spacer_body003/spacer_body004.-->
      <origin rpy="0 0 0" xyz="0.0 0.0 0.0"/>
      <geometry>
        <mesh filename="../meshes/robot_spacer_body_qdzdlv.dae"/>
      </geometry>
    </collision>
    <inertial>
        <mass value="0.00004"/>
        <origin xyz="0 0 0" rpy="0 0 0"/>
        <inertia ixx="0.00004" ixy="0" ixz="0" iyy="0.00004" iyz="0" izz="0.00004"/>
    </inertial>
  </link>
  <link name="spacer_br">
    <visual>
      <!--spacer_body005/spacer_body006.-->
      <origin rpy="0 0 0" xyz="0.0 0.0 0.0"/>
      <geometry>
        <mesh filename="../meshes/robot_spacer_body_rywx4e.dae"/>
      </geometry>
    </visual>
    <collision>
      <!--spacer_body005/spacer_body006.-->
      <origin rpy="0 0 0" xyz="0.0 0.0 0.0"/>
      <geometry>
        <mesh filename="../meshes/robot_spacer_body_sptmy1.dae"/>
      </geometry>
    </collision>
    <inertial>
        <mass value="0.00004"/>
        <origin xyz="0 0 0" rpy="0 0 0"/>
        <inertia ixx="0.00004" ixy="0" ixz="0" iyy="0.00004" iyz="0" izz="0.00004"/>
    </inertial>
  </link>
  <link name="spacer_bl">
    <visual>
      <!--spacer_body007/spacer_body008.-->
      <origin rpy="0 0 0" xyz="0.0 0.0 0.0"/>
      <geometry>
        <mesh filename="../meshes/robot_spacer_body_epfjej.dae"/>
      </geometry>
    </visual>
    <collision>
      <!--spacer_body007/spacer_body008.-->
      <origin rpy="0 0 0" xyz="0.0 0.0 0.0"/>
      <geometry>
        <mesh filename="../meshes/robot_spacer_body_en0t2a.dae"/>
      </geometry>
    </collision>
    <inertial>
        <mass value="0.00004"/>
        <origin xyz="0 0 0" rpy="0 0 0"/>
        <inertia ixx="0.00004" ixy="0" ixz="0" iyy="0.00004" iyz="0" izz="0.00004"/>
    </inertial>
  </link>
  <link name="leg_elbow_br">
    <visual>
      <!--elbow_br001/elbow_br001.-->
      <origin rpy="0 0 0" xyz="0.0 0.0 0.0"/>
      <geometry>
        <mesh filename="../meshes/robot_elbow_br_ijcs8k.dae"/>
      </geometry>
      <material name="blue"/>
    </visual>
    <collision>
      <!--elbow_br001/elbow_br001.-->
      <origin rpy="0 0 0" xyz="0.0 0.0 0.0"/>
      <geometry>
        <mesh filename="../meshes/robot_elbow_br_jcowuw.dae"/>
      </geometry>
    </collision>
    <inertial>
        <mass value="0.00282"/>
        <origin xyz="0.02227 -0.0022 0.00144" rpy="0 0 0"/>
        <inertia ixx="0.00282" ixy="0" ixz="0" iyy="0.00282" iyz="0" izz="0.00282"/>
    </inertial>
  </link>
  <link name="leg_elbow_bl">
    <visual>
      <!--elbow_bl001/elbow_bl001.-->
      <origin rpy="0 0 0" xyz="0.0 0.0 0.0"/>
      <geometry>
        <mesh filename="../meshes/robot_elbow_bl_22bifq.dae"/>
      </geometry>
      <material name="blue"/>
    </visual>
    <collision>
      <!--elbow_bl001/elbow_bl001.-->
      <origin rpy="0 0 0" xyz="0.0 0.0 0.0"/>
      <geometry>
        <mesh filename="../meshes/robot_elbow_bl_dyfjfb.dae"/>
      </geometry>
    </collision>
    <inertial>
        <mass value="0.00282"/>
        <origin xyz="0.02227 -0.0022 0.00144" rpy="0 0 0"/>
        <inertia ixx="0.00282" ixy="0" ixz="0" iyy="0.00282" iyz="0" izz="0.00282"/>
    </inertial>
  </link>
  <link name="leg_elbow_fl">
    <visual>
      <!--elbow_fl003/elbow_fl003.elbow_fl001.-->
      <origin rpy="0 0 0" xyz="0.0 0.0 0.0"/>
      <geometry>
        <mesh filename="../meshes/robot_elbow_fl_k9nt1j.dae"/>
      </geometry>
      <material name="blue"/>
    </visual>
    <collision>
      <!--Eje Z-->
      <origin rpy="-1.5707963267948963 0 -1.5707963267948963" xyz="0.0 0.0 0.0"/>
      <geometry>
        <mesh filename="../meshes/robot_elbow_fl_k9nt1j.dae"/>
      </geometry>
    </collision>
    <inertial>
        <mass value="0.00282"/>
        <origin xyz="0.02227 -0.0022 0.00144" rpy="0 0 0"/>
        <inertia ixx="0.00282" ixy="0" ixz="0" iyy="0.00282" iyz="0" izz="0.00282"/>
    </inertial>
  </link>
  <link name="leg_elbow_fr">
    <visual>
      <!--elbow_fr003/elbow_fr003.-->
      <origin rpy="0 0 0" xyz="0.0 0.0 0.0"/>
      <geometry>
        <mesh filename="../meshes/robot_elbow_fr_nicggp.dae"/>
      </geometry>
      <material name="blue"/>
    </visual>
    <collision>
      <!--elbow_fr003/elbow_fr003.-->
      <origin rpy="0 0 0" xyz="0.0 0.0 0.0"/>
      <geometry>
        <mesh filename="../meshes/robot_elbow_fr_y02wcm.dae"/>
      </geometry>
    </collision>
    <inertial>
        <mass value="0.00282"/>
        <origin xyz="0.02227 -0.0022 0.00144" rpy="0 0 0"/>
        <inertia ixx="0.00282" ixy="0" ixz="0" iyy="0.00282" iyz="0" izz="0.00282"/>
    </inertial>
  </link>
  <link name="leg_upper_axis_br">
    <visual>
      <!--upper_axis001/upper_axis001.-->
      <origin rpy="0 0 0" xyz="0.0 0.0 0.012"/>
      <geometry>
        <cylinder length="0.024" radius="0.0015"/>
      </geometry>
    </visual>
    <collision>
      <!--upper_axis001/upper_axis001.-->
      <origin rpy="0 0 0" xyz="0.0 0.0 0.012"/>
      <geometry>
        <cylinder length="0.024" radius="0.0015"/>
      </geometry>
    </collision>
    <inertial>
        <mass value="0"/>
        <origin xyz="0 0 0" rpy="0 0 0"/>
        <inertia ixx="0" ixy="0" ixz="0" iyy="0" iyz="0" izz="0"/>
    </inertial>
  </link>
  <link name="upper_link_br">
    <visual>
      <!--upper_link001/upper_link001.-->
      <origin rpy="0 0 0" xyz="0.0 0.0 0.0"/>
      <geometry>
        <mesh filename="../meshes/robot_upper_link_3mok0l.dae"/>
      </geometry>
    </visual>
    <collision>
      <!--upper_link001/upper_link001.-->
      <origin rpy="0 0 0" xyz="0.0 0.0 0.0"/>
      <geometry>
        <mesh filename="../meshes/robot_upper_link_3mok0l.dae"/>
      </geometry>
    </collision>
    <inertial>
        <mass value="0.000005"/>
        <origin xyz="-0.02181 0.00228 0.00003" rpy="0 0 0"/>
        <inertia ixx="0.000005" ixy="0" ixz="0" iyy="0.000005" iyz="0" izz="0.000005"/>
    </inertial>
  </link>
  <link name="leg_upper_axis_bl">
    <visual>
      <!--upper_axis003/upper_axis003.-->
      <origin rpy="0 0 0" xyz="0.0 0.0 0.012"/>
      <geometry>
        <cylinder length="0.024" radius="0.0015"/>
      </geometry>
    </visual>
    <collision>
      <!--upper_axis003/upper_axis003.-->
      <origin rpy="0 0 0" xyz="0.0 0.0 0.012"/>
      <geometry>
        <cylinder length="0.024" radius="0.0015"/>
      </geometry>
    </collision>
    <inertial>
        <mass value="0"/>
        <origin xyz="0 0 0" rpy="0 0 0"/>
        <inertia ixx="0" ixy="0" ixz="0" iyy="0" iyz="0" izz="0"/>
    </inertial>
  </link>
  <link name="upper_link_bl">
    <visual>
      <!--upper_link003/upper_link003.-->
      <origin rpy="0 0 0" xyz="0.0 0.0 0.0"/>
      <geometry>
        <mesh filename="../meshes/robot_upper_link_2rlvkm.dae"/>
      </geometry>
    </visual>
    <collision>
      <!--upper_link003/upper_link003.-->
      <origin rpy="0 0 0" xyz="0.0 0.0 0.0"/>
      <geometry>
        <mesh filename="../meshes/robot_upper_link_2rlvkm.dae"/>
      </geometry>
    </collision>
    <inertial>
        <mass value="0.000005"/>
        <origin xyz="-0.02181 0.00228 0.00003" rpy="0 0 0"/>
        <inertia ixx="0.000005" ixy="0" ixz="0" iyy="0.000005" iyz="0" izz="0.000005"/>
    </inertial>
  </link>
  <link name="leg_upper_axis_fl">
    <visual>
      <!--upper_axis005/upper_axis005.-->
      <origin rpy="0 0 0" xyz="0.0 0.0 0.012"/>
      <geometry>
        <cylinder length="0.024" radius="0.0015"/>
      </geometry>
    </visual>
    <collision>
      <!--upper_axis005/upper_axis005.-->
      <origin rpy="0 0 0" xyz="0.0 0.0 0.012"/>
      <geometry>
        <cylinder length="0.024" radius="0.0015"/>
      </geometry>
    </collision>
    <inertial>
        <mass value="0"/>
        <origin xyz="0 0 0" rpy="0 0 0"/>
        <inertia ixx="0" ixy="0" ixz="0" iyy="0" iyz="0" izz="0"/>
    </inertial>
  </link>
  <link name="upper_link_fl">
    <visual>
      <!--upper_link005/upper_link005.-->
      <origin rpy="0 0 0" xyz="0.0 0.0 0.0"/>
      <geometry>
        <mesh filename="../meshes/robot_upper_link_umbvcy.dae"/>
      </geometry>
    </visual>
    <collision>
      <!--upper_link005/upper_link005.-->
      <origin rpy="0 0 0" xyz="0.0 0.0 0.0"/>
      <geometry>
        <mesh filename="../meshes/robot_upper_link_umbvcy.dae"/>
      </geometry>
    </collision>
    <inertial>
        <mass value="0.000005"/>
        <origin xyz="-0.02181 0.00228 0.00003" rpy="0 0 0"/>
        <inertia ixx="0.000005" ixy="0" ixz="0" iyy="0.000005" iyz="0" izz="0.000005"/>
    </inertial>
  </link>
  <link name="leg_upper_axis_fr">
    <visual>
      <!--upper_axis007/upper_axis007.-->
      <origin rpy="0 0 0" xyz="0.0 0.0 0.012"/>
      <geometry>
        <cylinder length="0.024" radius="0.0015"/>
      </geometry>
    </visual>
    <collision>
      <!--upper_axis007/upper_axis007.-->
      <origin rpy="0 0 0" xyz="0.0 0.0 0.012"/>
      <geometry>
        <cylinder length="0.024" radius="0.0015"/>
      </geometry>
    </collision>
    <inertial>
        <mass value="0"/>
        <origin xyz="0 0 0" rpy="0 0 0"/>
        <inertia ixx="0" ixy="0" ixz="0" iyy="0" iyz="0" izz="0"/>
    </inertial>
  </link>
  <link name="upper_link_fr">
    <visual>
      <!--upper_link007/upper_link007.-->
      <origin rpy="0 0 0" xyz="0.0 0.0 0.0"/>
      <geometry>
        <mesh filename="../meshes/robot_upper_link_ggszxc.dae"/>
      </geometry>
    </visual>
    <collision>
      <!--upper_link007/upper_link007.-->
      <origin rpy="0 0 0" xyz="0.0 0.0 0.0"/>
      <geometry>
        <mesh filename="../meshes/robot_upper_link_ggszxc.dae"/>
      </geometry>
    </collision>
    <inertial>
        <mass value="0.000005"/>
        <origin xyz="-0.02181 0.00228 0.00003" rpy="0 0 0"/>
        <inertia ixx="0.000005" ixy="0" ixz="0" iyy="0.000005" iyz="0" izz="0.000005"/>
    </inertial>
  </link>
  <link name="leg_bottom_axis_br">
    <visual>
      <!--lower_axis002/lower_axis002.-->
      <origin rpy="0 0 0" xyz="0.0 0.0 0.01"/>
      <geometry>
        <cylinder length="0.02" radius="0.002"/>
      </geometry>
    </visual>
    <collision>
      <!--lower_axis002/lower_axis002.-->
      <origin rpy="0 0 0" xyz="0.0 0.0 0.01"/>
      <geometry>
        <cylinder length="0.02" radius="0.002"/>
      </geometry>
    </collision>
    <inertial>
        <mass value="0"/>
        <origin xyz="0 0 0" rpy="0 0 0"/>
        <inertia ixx="0" ixy="0" ixz="0" iyy="0" iyz="0" izz="0"/>
    </inertial>
  </link>
  <link name="leg_bottom_axis_fl">
    <visual>
      <!--lower_axis004/lower_axis003.-->
      <origin rpy="0 0 0" xyz="0.0 0.0 0.01"/>
      <geometry>
        <cylinder length="0.02" radius="0.002"/>
      </geometry>
    </visual>
    <collision>
      <!--lower_axis004/lower_axis003.-->
      <origin rpy="0 0 0" xyz="0.0 0.0 0.01"/>
      <geometry>
        <cylinder length="0.02" radius="0.002"/>
      </geometry>
    </collision>
    <inertial>
        <mass value="0"/>
        <origin xyz="0 0 0" rpy="0 0 0"/>
        <inertia ixx="0" ixy="0" ixz="0" iyy="0" iyz="0" izz="0"/>
    </inertial>
  </link>
  <link name="leg_bottom_link_br">
    <visual>
      <!--left_bottom_link001/left_bottom_link001.-->
      <origin rpy="0 0 0" xyz="0.0 0.0 0.0"/>
      <geometry>
        <mesh filename="../meshes/robot_left_bottom_link_mwapaw.dae"/>
      </geometry>
      <material name="red"/>
    </visual>
    <collision>
      <!--left_bottom_link001/left_bottom_link001.-->
      <origin rpy="0 0 0" xyz="0.0 0.0 0.0"/>
      <geometry>
        <mesh filename="../meshes/robot_left_bottom_link_mwapaw.dae"/>
      </geometry>
    </collision>
    <inertial>
        <mass value="0.00159"/>
        <origin xyz="0.0234 -0.0078 -0.0231" rpy="0 0 0"/>
        <inertia ixx="0.00159" ixy="0" ixz="0" iyy="0" iyz="0" izz="0.00159"/>
    </inertial>
  </link>
  <link name="leg_bottom_link_fl">
    <visual>
      <!--left_bottom_link005/left_bottom_link005.-->
      <origin rpy="0 0 0" xyz="0.0 0.0 0.0"/>
      <geometry>
        <mesh filename="../meshes/robot_left_bottom_link_54hzm8.dae"/>
      </geometry>
      <material name="red"/>
    </visual>
    <collision>
      <!--left_bottom_link005/left_bottom_link005.-->
      <origin rpy="0 0 0" xyz="0.0 0.0 0.0"/>
      <geometry>
        <mesh filename="../meshes/robot_left_bottom_link_54hzm8.dae"/>
      </geometry>
    </collision>
    <inertial>
        <mass value="0.00159"/>
        <origin xyz="0.0234 -0.0078 -0.0231" rpy="0 0 0"/>
        <inertia ixx="0.00159" ixy="0" ixz="0" iyy="0.00159" iyz="0" izz="0.00159"/>
    </inertial>
  </link>
  <link name="leg_bottom_axis_bl">
    <visual>
      <!--lower_axis008/lower_axis007.-->
      <origin rpy="0 0 0" xyz="0.0 0.0 0.01"/>
      <geometry>
        <cylinder length="0.02" radius="0.002"/>
      </geometry>
    </visual>
    <collision>
      <!--lower_axis008/lower_axis007.-->
      <origin rpy="0 0 0" xyz="0.0 0.0 0.01"/>
      <geometry>
        <cylinder length="0.02" radius="0.002"/>
      </geometry>
    </collision>
    <inertial>
        <mass value="0"/>
        <origin xyz="0 0 0" rpy="0 0 0"/>
        <inertia ixx="0" ixy="0" ixz="0" iyy="0" iyz="0" izz="0"/>
    </inertial>
  </link>
  <link name="leg_bottom_link_bl">
    <visual>
      <!--right_bottom_link001/right_bottom_link001.-->
      <origin rpy="0 0 0" xyz="0.0 0.0 0.0"/>
      <geometry>
        <mesh filename="../meshes/robot_right_bottom_link_nm1jks.dae"/>
      </geometry>
      <material name="red"/>
    </visual>
    <collision>
      <!--right_bottom_link001/right_bottom_link001.-->
      <origin rpy="0 0 0" xyz="0.0 0.0 0.0"/>
      <geometry>
        <mesh filename="../meshes/robot_right_bottom_link_nm1jks.dae"/>
      </geometry>
    </collision>
    <inertial>
        <mass value="0.00159"/>
        <origin xyz="0.0234 -0.0078 -0.0231" rpy="0 0 0"/>
        <inertia ixx="0.00159" ixy="0" ixz="0" iyy="0.00159" iyz="0" izz="0.00159"/>
    </inertial>
  </link>
  <link name="leg_bottom_axis_fr">
    <visual>
      <!--lower_axis010/lower_axis009.-->
      <origin rpy="0 0 0" xyz="0.0 0.0 0.01"/>
      <geometry>
        <cylinder length="0.02" radius="0.002"/>
      </geometry>
    </visual>
    <collision>
      <!--lower_axis010/lower_axis009.-->
      <origin rpy="0 0 0" xyz="0.0 0.0 0.01"/>
      <geometry>
        <cylinder length="0.02" radius="0.002"/>
      </geometry>
    </collision>
    <inertial>
        <mass value="0"/>
        <origin xyz="0 0 0" rpy="0 0 0"/>
        <inertia ixx="0" ixy="0" ixz="0" iyy="0" iyz="0" izz="0"/>
    </inertial>
  </link>
  <link name="leg_bottom_link_fr">
    <visual>
      <!--right_bottom_link003/right_bottom_link003.-->
      <origin rpy="0 0 0" xyz="0.0 0.0 0.0"/>
      <geometry>
        <mesh filename="../meshes/robot_right_bottom_link_eam2j3.dae"/>
      </geometry>
      <material name="red"/>
    </visual>
    <collision>
      <!--right_bottom_link003/right_bottom_link003.-->
      <origin rpy="0 0 0" xyz="0.0 0.0 0.0"/>
      <geometry>
        <mesh filename="../meshes/robot_right_bottom_link_eam2j3.dae"/>
      </geometry>
    </collision>
    <inertial>
        <mass value="0.00159"/>
        <origin xyz="0.0234 -0.0078 -0.0231" rpy="0 0 0"/>
        <inertia ixx="0.00159" ixy="0" ixz="0" iyy="0.00159" iyz="0" izz="0.00159"/>
    </inertial>
  </link>
  <link name="foot_axis_fr">
    <visual>
      <!--foot_axis001/foot_axis001.-->
      <origin rpy="0 0 0" xyz="0.0 0.0 0.0065"/>
      <geometry>
        <cylinder length="0.013" radius="0.0015"/>
      </geometry>
    </visual>
    <collision>
      <!--foot_axis001/foot_axis001.-->
      <origin rpy="0 0 0" xyz="0.0 0.0 0.0065"/>
      <geometry>
        <cylinder length="0.013" radius="0.0015"/>
      </geometry>
    </collision>
    <inertial>
        <mass value="0"/>
        <origin xyz="0 0 0" rpy="0 0 0"/>
        <inertia ixx="0" ixy="0" ixz="0" iyy="0" iyz="0" izz="0"/>
    </inertial>
  </link>
  <link name="foot_link_fr">
    <visual>
      <!--foot001/foot001.-->
      <origin rpy="0 0 0" xyz="0.0 0.0 0.0"/>
      <geometry>
        <mesh filename="../meshes/robot_foot_6evywk.dae"/>
      </geometry>
      <material name="green"/>
    </visual>
    <collision>
      <!--foot001/foot001.-->
      <origin rpy="0 0 0" xyz="0.0 0.0 0.0"/>
      <geometry>
        <mesh filename="../meshes/robot_foot_6evywk.dae"/>
      </geometry>
    </collision>
    <inertial>
        <mass value="0.00294"/>
        <origin xyz="-0.01032 0.00349 0" rpy="0 0 0"/>
        <inertia ixx="0.00294" ixy="0" ixz="0" iyy="0.00294" iyz="0" izz="0.00294"/>
    </inertial>
  </link>
  <link name="foot_axis_br">
    <visual>
      <!--foot_axis003/foot_axis003.-->
      <origin rpy="0 0 0" xyz="0.0 0.0 0.0065"/>
      <geometry>
        <cylinder length="0.013" radius="0.0015"/>
      </geometry>
    </visual>
    <collision>
      <!--foot_axis003/foot_axis003.-->
      <origin rpy="0 0 0" xyz="0.0 0.0 0.0065"/>
      <geometry>
        <cylinder length="0.013" radius="0.0015"/>
      </geometry>
    </collision>
    <inertial>
        <mass value="0"/>
        <origin xyz="0 0 0" rpy="0 0 0"/>
        <inertia ixx="0" ixy="0" ixz="0" iyy="0" iyz="0" izz="0"/>
    </inertial>
  </link>
  <link name="foot_link_br">
    <visual>
      <!--foot003/foot003.-->
      <origin rpy="0 0 0" xyz="0.0 0.0 0.0"/>
      <geometry>
        <mesh filename="../meshes/robot_foot_eruimg.dae"/>
      </geometry>
      <material name="green"/>
    </visual>
    <collision>
      <!--foot003/foot003.-->
      <origin rpy="0 0 0" xyz="0.0 0.0 0.0"/>
      <geometry>
        <mesh filename="../meshes/robot_foot_eruimg.dae"/>
      </geometry>
    </collision>
    <inertial>
        <mass value="0.00294"/>
        <origin xyz="-0.01032 0.00349 0" rpy="0 0 0"/>
        <inertia ixx="0.00294" ixy="0" ixz="0" iyy="0.00294" iyz="0" izz="0.00294"/>
    </inertial>
  </link>
  <link name="foot_axis_fl">
    <visual>
      <!--foot_axis005/foot_axis005.-->
      <origin rpy="0 0 0" xyz="0.0 0.0 0.0065"/>
      <geometry>
        <cylinder length="0.013" radius="0.0015"/>
      </geometry>
    </visual>
    <collision>
      <!--foot_axis005/foot_axis005.-->
      <origin rpy="0 0 0" xyz="0.0 0.0 0.0065"/>
      <geometry>
        <cylinder length="0.013" radius="0.0015"/>
      </geometry>
    </collision>
    <inertial>
        <mass value="0"/>
        <origin xyz="0 0 0" rpy="0 0 0"/>
        <inertia ixx="0" ixy="0" ixz="0" iyy="0" iyz="0" izz="0"/>
    </inertial>
  </link>
  <link name="foot_link_fl">
    <visual>
      <!--foot005/foot005.-->
      <origin rpy="0 0 0" xyz="0.0 0.0 0.0"/>
      <geometry>
        <mesh filename="../meshes/robot_foot_z7rhv3.dae"/>
      </geometry>
      <material name="green"/>
    </visual>
    <collision>
      <!--foot005/foot005.-->
      <origin rpy="0 0 0" xyz="0.0 0.0 0.0"/>
      <geometry>
        <mesh filename="../meshes/robot_foot_z7rhv3.dae"/>
      </geometry>
    </collision>
    <inertial>
        <mass value="0.00294"/>
        <origin xyz="-0.01032 0.00349 0" rpy="0 0 0"/>
        <inertia ixx="0.00294" ixy="0" ixz="0" iyy="0.00294" iyz="0" izz="0.00294"/>
    </inertial>
  </link>
  <link name="foot_axis_bl">
    <visual>
      <!--foot_axis007/foot_axis007.-->
      <origin rpy="0 0 0" xyz="0.0 0.0 0.0065"/>
      <geometry>
        <cylinder length="0.013" radius="0.0015"/>
      </geometry>
    </visual>
    <collision>
      <!--foot_axis007/foot_axis007.-->
      <origin rpy="0 0 0" xyz="0.0 0.0 0.0065"/>
      <geometry>
        <cylinder length="0.013" radius="0.0015"/>
      </geometry>
    </collision>
    <inertial>
        <mass value="0"/>
        <origin xyz="0 0 0" rpy="0 0 0"/>
        <inertia ixx="0" ixy="0" ixz="0" iyy="0" iyz="0" izz="0"/>
    </inertial>
  </link>
  <link name="foot_link_bl">
    <visual>
      <!--foot007/foot007.-->
      <origin rpy="0 0 0" xyz="0.0 0.0 0.0"/>
      <geometry>
        <mesh filename="../meshes/robot_foot_wkfqst.dae"/>
      </geometry>
      <material name="green"/>
    </visual>
    <collision>
      <!--foot007/foot007.-->
      <origin rpy="0 0 0" xyz="0.0 0.0 0.0"/>
      <geometry>
        <mesh filename="../meshes/robot_foot_wkfqst.dae"/>
      </geometry>
    </collision>
    <inertial>
        <mass value="0.00294"/>
        <origin xyz="-0.01032 0.00349 0" rpy="0 0 0"/>
        <inertia ixx="0.00294" ixy="0" ixz="0" iyy="0.00294" iyz="0" izz="0.00294"/>
    </inertial>
  </link>
  <link name="servo_br_chasis">
    <visual>
      <!--servo001/servo001.-->
      <origin rpy="0 0 0" xyz="0.0 0.0 0.0"/>
      <geometry>
        <mesh filename="../meshes/robot_servo_gzkmtc.dae"/>
      </geometry>
    </visual>
    <collision>
      <!--servo001/servo001.-->
      <origin rpy="0 0 0" xyz="0.0 0.0 0.0"/>
      <geometry>
        <mesh filename="../meshes/robot_servo_gzkmtc.dae"/>
      </geometry>
    </collision>
    <inertial>
        <mass value="0.009"/>
        <origin xyz="0 0 0" rpy="0 0 0"/>
        <inertia ixx="0.009" ixy="0" ixz="0" iyy="0.009" iyz="0" izz="0.009"/>
    </inertial>
  </link>
  <link name="servo_fr_chasis">
    <visual>
      <!--servo003/servo003.-->
      <origin rpy="0 0 0" xyz="0.0 0.0 0.0"/>
      <geometry>
        <mesh filename="../meshes/robot_servo_lm7nas.dae"/>
      </geometry>
    </visual>
    <collision>
      <!--servo003/servo003.-->
      <origin rpy="0 0 0" xyz="0.0 0.0 0.0"/>
      <geometry>
        <mesh filename="../meshes/robot_servo_lm7nas.dae"/>
      </geometry>
    </collision>
    <inertial>
        <mass value="0.009"/>
        <origin xyz="0 0 0" rpy="0 0 0"/>
        <inertia ixx="0.009" ixy="0" ixz="0" iyy="0.009" iyz="0" izz="0.009"/>
    </inertial>
  </link>
  <link name="servo_bl_chasis">
    <visual>
      <!--servo005/servo005.-->
      <origin rpy="0 0 0" xyz="0.0 0.0 0.0"/>
      <geometry>
        <mesh filename="../meshes/robot_servo_uk13q0.dae"/>
      </geometry>
    </visual>
    <collision>
      <!--servo005/servo005.-->
      <origin rpy="0 0 0" xyz="0.0 0.0 0.0"/>
      <geometry>
        <mesh filename="../meshes/robot_servo_uk13q0.dae"/>
      </geometry>
    </collision>
    <inertial>
        <mass value="0.009"/>
        <origin xyz="0 0 0" rpy="0 0 0"/>
        <inertia ixx="0.009" ixy="0" ixz="0" iyy="0.009" iyz="0" izz="0.009"/>
    </inertial>
  </link>
  <link name="servo_fl_chasis">
    <visual>
      <!--servo007/servo007.-->
      <origin rpy="0 0 0" xyz="0.0 0.0 0.0"/>
      <geometry>
        <mesh filename="../meshes/robot_servo_oiqija.dae"/>
      </geometry>
    </visual>
    <collision>
      <!--servo007/servo007.-->
      <origin rpy="0 0 0" xyz="0.0 0.0 0.0"/>
      <geometry>
        <mesh filename="../meshes/robot_servo_oiqija.dae"/>
      </geometry>
    </collision>
    <inertial>
        <mass value="0.009"/>
        <origin xyz="0 0 0" rpy="0 0 0"/>
        <inertia ixx="0.009" ixy="0" ixz="0" iyy="0.009" iyz="0" izz="0.009"/>
    </inertial>
  </link>
  <link name="servo_br_leg">
    <visual>
      <!--servo009/servo009.-->
      <origin rpy="0 0 0" xyz="0.0 0.0 0.0"/>
      <geometry>
        <mesh filename="../meshes/robot_servo_o5juby.dae"/>
      </geometry>
    </visual>
    <collision>
      <!--servo009/servo009.-->
      <origin rpy="0 0 0" xyz="0.0 0.0 0.0"/>
      <geometry>
        <mesh filename="../meshes/robot_servo_o5juby.dae"/>
      </geometry>
    </collision>
    <inertial>
        <mass value="0.009"/>
        <origin xyz="0 0 0" rpy="0 0 0"/>
        <inertia ixx="0.009" ixy="0" ixz="0" iyy="0.009" iyz="0" izz="0.009"/>
    </inertial>
  </link>
  <link name="servo_fr_leg">
    <visual>
      <!--servo011/servo011.-->
      <origin rpy="0 0 0" xyz="0.0 0.0 0.0"/>
      <geometry>
        <mesh filename="../meshes/robot_servo_kbicgk.dae"/>
      </geometry>
    </visual>
    <collision>
      <!--servo011/servo011.-->
      <origin rpy="0 0 0" xyz="0.0 0.0 0.0"/>
      <geometry>
        <mesh filename="../meshes/robot_servo_kbicgk.dae"/>
      </geometry>
    </collision>
    <inertial>
        <mass value="0.009"/>
        <origin xyz="0 0 0" rpy="0 0 0"/>
        <inertia ixx="0.009" ixy="0" ixz="0" iyy="0.009" iyz="0" izz="0.009"/>
    </inertial>
  </link>
  <link name="servo_bl_leg">
    <visual>
      <!--servo013/servo013.-->
      <origin rpy="0 0 0" xyz="0.0 0.0 0.0"/>
      <geometry>
        <mesh filename="../meshes/robot_servo_yposhh.dae"/>
      </geometry>
    </visual>
    <collision>
      <!--servo013/servo013.-->
      <origin rpy="0 0 0" xyz="0.0 0.0 0.0"/>
      <geometry>
        <mesh filename="../meshes/robot_servo_yposhh.dae"/>
      </geometry>
    </collision>
    <inertial>
        <mass value="0.009"/>
        <origin xyz="0 0 0" rpy="0 0 0"/>
        <inertia ixx="0.009" ixy="0" ixz="0" iyy="0.009" iyz="0" izz="0.009"/>
    </inertial>
  </link>
  <link name="servo_fl_leg">
    <visual>
      <!--servo015/servo015.-->
      <origin rpy="0 0 0" xyz="0.0 0.0 0.0"/>
      <geometry>
        <mesh filename="../meshes/robot_servo_iojgfp.dae"/>
      </geometry>
    </visual>
    <collision>
      <!--servo015/servo015.-->
      <origin rpy="0 0 0" xyz="0.0 0.0 0.0"/>
      <geometry>
        <mesh filename="../meshes/robot_servo_iojgfp.dae"/>
      </geometry>
    </collision>
    <inertial>
        <mass value="0.009"/>
        <origin xyz="0 0 0" rpy="0 0 0"/>
        <inertia ixx="0.009" ixy="0" ixz="0" iyy="0.009" iyz="0" izz="0.009"/>
    </inertial>
  </link>
  <link name="up_box_link">
    <visual>
      <origin rpy="0 0 0" xyz="0.0 0.0 0.0"/>
      <geometry>
        <mesh filename="../meshes/robot_up_box_hkhjvv.dae"/>
      </geometry>
    </visual>
    <collision>
      <origin rpy="0 0 0" xyz="0.0 0.0 0.0"/>
      <geometry>
        <mesh filename="../meshes/robot_up_box_hkhjvv.dae"/>
      </geometry>
    </collision>
    <inertial>
        <mass value="0.03146"/>
        <origin xyz="-0.000269 0.00184 0.002399" rpy="0 0 0"/>
        <inertia ixx="0.03146" ixy="0" ixz="0" iyy="0" iyz="0" izz="0.03146"/>
    </inertial>
  </link>
  <link name="battery">
    <visual>
      <origin rpy="0 0 0" xyz="0.028 0.035 0.009"/>
      <geometry>
        <box size="0.056 0.07 0.018"/>
      </geometry>
    </visual>
    <collision>
      <origin rpy="0 0 0" xyz="0.028 0.035 0.009"/>
      <geometry>
        <box size="0.056 0.07 0.018"/>
      </geometry>
    </collision>
    <inertial>
        <mass value="0.0002"/>
        <origin xyz="0 0 0" rpy="0 0 0"/>
        <inertia ixx="0.2" ixy="0" ixz="0" iyy="0.2" iyz="0" izz="0.2"/>
    </inertial>
  </link>

  <material name="blue">
    <color rgba="0 0 1 1"/>
  </material>
  <material name="red">
    <color rgba="1 0 0 1"/>
  </material>
  <material name="green">
    <color rgba="0 1 0 1"/>
  </material>

</robot>
